Workbook

Sheet Cover
A1: NIKE, Inc.: Five-Year Financial Forecast
A2: Three-statement model: FY2024 to FY2026 actual, FY2027 to FY2031 forecast (years ending 31 May). $ millions.
A4: Purpose | B4: Forecast Nike's revenue, profit and cash flow for five years under base, upside and downside scenarios.
A5: Selected scenario | B5: =Assumptions!C6 -> Base case
A6: Revenue | B6: Built up by region (North America, EMEA, Greater China, APLA, Converse), each with its own growth rate per scenario.
A7: Costs | B7: Gross margin by scenario; marketing (demand creation) and overhead as a % of revenue.
A8: Statements | B8: Linked income statement, balance sheet and cash flow. Cash is the balancing item; the balance sheet balances every year.
A10: Sheets
A11: Summary | B11: Key outputs and charts for the selected scenario
A12: Assumptions | B12: Every driver, with base / upside / downside tables. Change cell B6 to switch scenario.
A13: Revenue Build | B13: Revenue by region, growth and mix
A14: Income Statement / Balance Sheet / Cash Flow | B14: The three linked statements
A15: Scenarios | B15: All three scenarios side by side
A16: Checks | B16: Balance sheet, cash and source checks
A18: Sources | B18: NIKE, Inc. Form 10-K filings (FY2024 to FY2026) and fiscal 2026 fourth quarter results release (revenue by region).
A19: Note | B19: The forecast assumptions are my own judgement for this exercise, not company guidance.
A20: Colour key | B20: Blue = input, black = formula, green = link to another sheet, yellow = key assumption, grey = actual (history)
A21: Checks status | B21: =Checks!B13 -> OK

Sheet Summary
A1: Nike Five-Year Forecast: Summary
A2: Selected scenario shown. Change the scenario on the Assumptions sheet (cell B6).
A3: ="Scenario: "&Assumptions!C6 -> Scenario: Base case
A4: $ millions unless stated | B4: FY2024A | C4: FY2025A | D4: FY2026A | E4: FY2027E | F4: FY2028E | G4: FY2029E | H4: FY2030E | I4: FY2031E
A5: Revenue | B5: ='Income Statement'!B5 -> 51362 | C5: ='Income Statement'!C5 -> 46309 | D5: ='Income Statement'!D5 -> 46398 | E5: ='Income Statement'!E5 -> 47184.99 | F5: ='Income Statement'!F5 -> 48859.282 | G5: ='Income Statement'!G5 -> 51025.774 | H5: ='Income Statement'!H5 -> 53113.394 | I5: ='Income Statement'!I5 -> 55144.718
A6: Revenue growth | C6: ='Revenue Build'!C20 -> -0.098380125 | D6: ='Revenue Build'!D20 -> 0.0019218726 | E6: ='Revenue Build'!E20 -> 0.016961722 | F6: ='Revenue Build'!F20 -> 0.035483564 | G6: ='Revenue Build'!G20 -> 0.044341474 | H6: ='Revenue Build'!H20 -> 0.040913049 | I6: ='Revenue Build'!I20 -> 0.038245046
A7: Gross margin | B7: ='Income Statement'!B22 -> 0.44560181 | C7: ='Income Statement'!C22 -> 0.42734674 | D7: ='Income Statement'!D22 -> 0.42913488 | E7: ='Income Statement'!E22 -> 0.43 | F7: ='Income Statement'!F22 -> 0.435 | G7: ='Income Statement'!G22 -> 0.44 | H7: ='Income Statement'!H22 -> 0.445 | I7: ='Income Statement'!I22 -> 0.445
A8: Operating income (EBIT) | B8: ='Income Statement'!B10 -> 6311 | C8: ='Income Statement'!C10 -> 3702 | D8: ='Income Statement'!D10 -> 3797 | E8: ='Income Statement'!E10 -> 4105.0941 | F8: ='Income Statement'!F10 -> 4739.3503 | G8: ='Income Statement'!G10 -> 5459.7578 | H8: ='Income Statement'!H10 -> 6108.0403 | I8: ='Income Statement'!I10 -> 6451.9321
A9: EBIT margin | B9: ='Income Statement'!B25 -> 0.12287294 | C9: ='Income Statement'!C25 -> 0.079941264 | D9: ='Income Statement'!D25 -> 0.081835424 | E9: ='Income Statement'!E25 -> 0.087 | F9: ='Income Statement'!F25 -> 0.097 | G9: ='Income Statement'!G25 -> 0.107 | H9: ='Income Statement'!H25 -> 0.115 | I9: ='Income Statement'!I25 -> 0.117
A10: Net income | B10: ='Income Statement'!B15 -> 5700 | C10: ='Income Statement'!C15 -> 3219 | D10: ='Income Statement'!D15 -> 3108 | E10: ='Income Statement'!E15 -> 3323.7209 | F10: ='Income Statement'!F15 -> 3874.928 | G10: ='Income Statement'!G15 -> 4465.8093 | H10: ='Income Statement'!H15 -> 4998.8905 | I10: ='Income Statement'!I15 -> 5275.9148
A11: Diluted EPS ($) | B11: ='Income Statement'!B18 -> 3.7262208 | C11: ='Income Statement'!C18 -> 2.1638881 | D11: ='Income Statement'!D18 -> 2.098582 | E11: ='Income Statement'!E18 -> 2.2523521 | F11: ='Income Statement'!F18 -> 2.659525 | G11: ='Income Statement'!G18 -> 3.119308 | H11: ='Income Statement'!H18 -> 3.5714864 | I11: ='Income Statement'!I18 -> 3.8764988
A12: Cash from operations | B12: ='Cash Flow'!B15 -> 7429 | C12: ='Cash Flow'!C15 -> 3698 | D12: ='Cash Flow'!D15 -> 2868 | E12: ='Cash Flow'!E15 -> 5308.8187 | F12: ='Cash Flow'!F15 -> 5651.766 | G12: ='Cash Flow'!G15 -> 6291.2085 | H12: ='Cash Flow'!H15 -> 6560.9688 | I12: ='Cash Flow'!I15 -> 6796.4601
A13: Free cash flow | B13: ='Cash Flow'!B35 -> 6617 | C13: ='Cash Flow'!C35 -> 3268 | D13: ='Cash Flow'!D35 -> 2184 | E13: ='Cash Flow'!E35 -> 4553.8589 | F13: ='Cash Flow'!F35 -> 4870.0175 | G13: ='Cash Flow'!G35 -> 5474.7961 | H13: ='Cash Flow'!H35 -> 5711.1545 | I13: ='Cash Flow'!I35 -> 5914.1446
A14: Cash returned to shareholders | B14: ='Cash Flow'!B36 -> 6419 | C14: ='Cash Flow'!C36 -> 5285 | D14: ='Cash Flow'!D36 -> 2553 | E14: ='Cash Flow'!E36 -> 3518.2486 | F14: ='Cash Flow'!F36 -> 4610.7133 | G14: ='Cash Flow'!G36 -> 5193.586 | H14: ='Cash Flow'!H36 -> 5765.0491 | I14: ='Cash Flow'!I36 -> 6323.096
A15: Cash and short-term investments | B15: ='Balance Sheet'!B6+'Balance Sheet'!B7 -> 11582 | C15: ='Balance Sheet'!C6+'Balance Sheet'!C7 -> 9151 | D15: ='Balance Sheet'!D6+'Balance Sheet'!D7 -> 9027 | E15: ='Balance Sheet'!E6+'Balance Sheet'!E7 -> 8062.6103 | F15: ='Balance Sheet'!F6+'Balance Sheet'!F7 -> 8321.9145 | G15: ='Balance Sheet'!G6+'Balance Sheet'!G7 -> 8603.1247 | H15: ='Balance Sheet'!H6+'Balance Sheet'!H7 -> 8549.23 | I15: ='Balance Sheet'!I6+'Balance Sheet'!I7 -> 8140.2786
A16: Total debt | B16: ='Balance Sheet'!B19+'Balance Sheet'!B25 -> 8909 | C16: ='Balance Sheet'!C19+'Balance Sheet'!C25 -> 7966 | D16: ='Balance Sheet'!D19+'Balance Sheet'!D25 -> 7942 | E16: ='Balance Sheet'!E19+'Balance Sheet'!E25 -> 5942 | F16: ='Balance Sheet'!F19+'Balance Sheet'!F25 -> 5942 | G16: ='Balance Sheet'!G19+'Balance Sheet'!G25 -> 5942 | H16: ='Balance Sheet'!H19+'Balance Sheet'!H25 -> 5942 | I16: ='Balance Sheet'!I19+'Balance Sheet'!I25 -> 5942
A18: Checks status | B18: =Checks!B13 -> OK

Sheet Assumptions
A1: Assumptions
A2: Blue = input you can change. Yellow = key assumption. Forecast years only; history shown grey for reference.
A4: $ millions unless stated | B4: FY2024A | C4: FY2025A | D4: FY2026A | E4: FY2027E | F4: FY2028E | G4: FY2029E | H4: FY2030E | I4: FY2031E
A6: Scenario (1 = Base, 2 = Upside, 3 = Downside) | B6: 1 | C6: =CHOOSE(B6,"Base case","Upside case","Downside case") -> Base case
A8: Revenue growth by region: selected scenario
A9: North America | E9: =CHOOSE(Assumptions!$B$6,E16,E23,E30) -> 0.04 | F9: =CHOOSE(Assumptions!$B$6,F16,F23,F30) -> 0.05 | G9: =CHOOSE(Assumptions!$B$6,G16,G23,G30) -> 0.05 | H9: =CHOOSE(Assumptions!$B$6,H16,H23,H30) -> 0.04 | I9: =CHOOSE(Assumptions!$B$6,I16,I23,I30) -> 0.04
A10: Europe, Middle East & Africa | E10: =CHOOSE(Assumptions!$B$6,E17,E24,E31) -> 0.02 | F10: =CHOOSE(Assumptions!$B$6,F17,F24,F31) -> 0.03 | G10: =CHOOSE(Assumptions!$B$6,G17,G24,G31) -> 0.04 | H10: =CHOOSE(Assumptions!$B$6,H17,H24,H31) -> 0.04 | I10: =CHOOSE(Assumptions!$B$6,I17,I24,I31) -> 0.03
A11: Greater China | E11: =CHOOSE(Assumptions!$B$6,E18,E25,E32) -> -0.05 | F11: =CHOOSE(Assumptions!$B$6,F18,F25,F32) -> 0 | G11: =CHOOSE(Assumptions!$B$6,G18,G25,G32) -> 0.03 | H11: =CHOOSE(Assumptions!$B$6,H18,H25,H32) -> 0.04 | I11: =CHOOSE(Assumptions!$B$6,I18,I25,I32) -> 0.04
A12: Asia Pacific & Latin America | E12: =CHOOSE(Assumptions!$B$6,E19,E26,E33) -> 0.02 | F12: =CHOOSE(Assumptions!$B$6,F19,F26,F33) -> 0.04 | G12: =CHOOSE(Assumptions!$B$6,G19,G26,G33) -> 0.05 | H12: =CHOOSE(Assumptions!$B$6,H19,H26,H33) -> 0.05 | I12: =CHOOSE(Assumptions!$B$6,I19,I26,I33) -> 0.05
A13: Converse | E13: =CHOOSE(Assumptions!$B$6,E20,E27,E34) -> -0.1 | F13: =CHOOSE(Assumptions!$B$6,F20,F27,F34) -> -0.03 | G13: =CHOOSE(Assumptions!$B$6,G20,G27,G34) -> 0.02 | H13: =CHOOSE(Assumptions!$B$6,H20,H27,H34) -> 0.02 | I13: =CHOOSE(Assumptions!$B$6,I20,I27,I34) -> 0.02
A15: Revenue growth by region: Base case
A16: North America | E16: 0.04 | F16: 0.05 | G16: 0.05 | H16: 0.04 | I16: 0.04
A17: Europe, Middle East & Africa | E17: 0.02 | F17: 0.03 | G17: 0.04 | H17: 0.04 | I17: 0.03
A18: Greater China | E18: -0.05 | F18: 0 | G18: 0.03 | H18: 0.04 | I18: 0.04
A19: Asia Pacific & Latin America | E19: 0.02 | F19: 0.04 | G19: 0.05 | H19: 0.05 | I19: 0.05
A20: Converse | E20: -0.1 | F20: -0.03 | G20: 0.02 | H20: 0.02 | I20: 0.02
A22: Revenue growth by region: Upside case
A23: North America | E23: 0.06 | F23: 0.07 | G23: 0.07 | H23: 0.06 | I23: 0.05
A24: Europe, Middle East & Africa | E24: 0.04 | F24: 0.05 | G24: 0.06 | H24: 0.05 | I24: 0.04
A25: Greater China | E25: 0 | F25: 0.05 | G25: 0.06 | H25: 0.06 | I25: 0.05
A26: Asia Pacific & Latin America | E26: 0.04 | F26: 0.06 | G26: 0.07 | H26: 0.07 | I26: 0.06
A27: Converse | E27: -0.05 | F27: 0.02 | G27: 0.04 | H27: 0.04 | I27: 0.03
A29: Revenue growth by region: Downside case
A30: North America | E30: 0.01 | F30: 0.02 | G30: 0.02 | H30: 0.02 | I30: 0.02
A31: Europe, Middle East & Africa | E31: -0.02 | F31: 0 | G31: 0.01 | H31: 0.02 | I31: 0.02
A32: Greater China | E32: -0.12 | F32: -0.06 | G32: -0.02 | H32: 0 | I32: 0.01
A33: Asia Pacific & Latin America | E33: -0.01 | F33: 0.01 | G33: 0.02 | H33: 0.03 | I33: 0.03
A34: Converse | E34: -0.18 | F34: -0.08 | G34: -0.03 | H34: 0 | I34: 0
A36: Global Brand Divisions and Corporate ($m, held flat) | E36: 51 | F36: 51 | G36: 51 | H36: 51 | I36: 51
A38: Margins and costs (% of revenue)
A39: Gross margin: base | E39: 0.43 | F39: 0.435 | G39: 0.44 | H39: 0.445 | I39: 0.445
A40: Gross margin: upside | E40: 0.435 | F40: 0.445 | G40: 0.455 | H40: 0.46 | I40: 0.46
A41: Gross margin: downside | E41: 0.425 | F41: 0.425 | G41: 0.428 | H41: 0.43 | I41: 0.43
A42: Gross margin: selected scenario | E42: =CHOOSE(Assumptions!$B$6,E39,E40,E41) -> 0.43 | F42: =CHOOSE(Assumptions!$B$6,F39,F40,F41) -> 0.435 | G42: =CHOOSE(Assumptions!$B$6,G39,G40,G41) -> 0.44 | H42: =CHOOSE(Assumptions!$B$6,H39,H40,H41) -> 0.445 | I42: =CHOOSE(Assumptions!$B$6,I39,I40,I41) -> 0.445
A43: Demand creation (marketing) | E43: 0.1 | F43: 0.098 | G43: 0.096 | H43: 0.095 | I43: 0.095
A44: Operating overhead | E44: 0.243 | F44: 0.24 | G44: 0.237 | H44: 0.235 | I44: 0.233
A45: Depreciation and amortization | E45: 0.016 | F45: 0.016 | G45: 0.016 | H45: 0.016 | I45: 0.016
A46: Stock-based compensation (non-cash, inside overhead) | E46: 0.015 | F46: 0.015 | G46: 0.015 | H46: 0.015 | I46: 0.015
A47: Capital expenditure | E47: 0.016 | F47: 0.016 | G47: 0.016 | H47: 0.016 | I47: 0.016
A49: Tax and interest
...

Sheet Revenue Build
A1: Revenue Build by Region
A2: FY2025 and FY2026 actual revenue by region from Nike's fiscal 2026 results; forecast = prior year x (1 + growth).
A4: $ millions unless stated | B4: FY2024A | C4: FY2025A | D4: FY2026A | E4: FY2027E | F4: FY2028E | G4: FY2029E | H4: FY2030E | I4: FY2031E
A5: Revenue ($m)
A6: North America | C6: 19572 | D6: 20511 | E6: =D6*(1+Assumptions!E9) -> 21331.44 | F6: =E6*(1+Assumptions!F9) -> 22398.012 | G6: =F6*(1+Assumptions!G9) -> 23517.913 | H6: =G6*(1+Assumptions!H9) -> 24458.629 | I6: =H6*(1+Assumptions!I9) -> 25436.974
A7: Europe, Middle East & Africa | C7: 12257 | D7: 12572 | E7: =D7*(1+Assumptions!E10) -> 12823.44 | F7: =E7*(1+Assumptions!F10) -> 13208.143 | G7: =F7*(1+Assumptions!G10) -> 13736.469 | H7: =G7*(1+Assumptions!H10) -> 14285.928 | I7: =H7*(1+Assumptions!I10) -> 14714.506
A8: Greater China | C8: 6586 | D8: 5847 | E8: =D8*(1+Assumptions!E11) -> 5554.65 | F8: =E8*(1+Assumptions!F11) -> 5554.65 | G8: =F8*(1+Assumptions!G11) -> 5721.2895 | H8: =G8*(1+Assumptions!H11) -> 5950.1411 | I8: =H8*(1+Assumptions!I11) -> 6188.1467
A9: Asia Pacific & Latin America | C9: 6251 | D9: 6243 | E9: =D9*(1+Assumptions!E12) -> 6367.86 | F9: =E9*(1+Assumptions!F12) -> 6622.5744 | G9: =F9*(1+Assumptions!G12) -> 6953.7031 | H9: =G9*(1+Assumptions!H12) -> 7301.3883 | I9: =H9*(1+Assumptions!I12) -> 7666.4577
A10: Converse | C10: 1692 | D10: 1174 | E10: =D10*(1+Assumptions!E13) -> 1056.6 | F10: =E10*(1+Assumptions!F13) -> 1024.902 | G10: =F10*(1+Assumptions!G13) -> 1045.4 | H10: =G10*(1+Assumptions!H13) -> 1066.308 | I10: =H10*(1+Assumptions!I13) -> 1087.6342
A11: Global Brand Divisions and Corporate | C11: -49 | D11: 51 | E11: =Assumptions!E36 -> 51 | F11: =Assumptions!F36 -> 51 | G11: =Assumptions!G36 -> 51 | H11: =Assumptions!H36 -> 51 | I11: =Assumptions!I36 -> 51
A12: Total revenue | B12: 51362 | C12: =SUM(C6:C11) -> 46309 | D12: =SUM(D6:D11) -> 46398 | E12: =SUM(E6:E11) -> 47184.99 | F12: =SUM(F6:F11) -> 48859.282 | G12: =SUM(G6:G11) -> 51025.774 | H12: =SUM(H6:H11) -> 53113.394 | I12: =SUM(I6:I11) -> 55144.718
A14: Growth
A15: North America | D15: =D6/C6-1 -> 0.047976701 | E15: =E6/D6-1 -> 0.04 | F15: =F6/E6-1 -> 0.05 | G15: =G6/F6-1 -> 0.05 | H15: =H6/G6-1 -> 0.04 | I15: =I6/H6-1 -> 0.04
A16: Europe, Middle East & Africa | D16: =D7/C7-1 -> 0.0256996 | E16: =E7/D7-1 -> 0.02 | F16: =F7/E7-1 -> 0.03 | G16: =G7/F7-1 -> 0.04 | H16: =H7/G7-1 -> 0.04 | I16: =I7/H7-1 -> 0.03
A17: Greater China | D17: =D8/C8-1 -> -0.11220771 | E17: =E8/D8-1 -> -0.05 | F17: =F8/E8-1 -> 0 | G17: =G8/F8-1 -> 0.03 | H17: =H8/G8-1 -> 0.04 | I17: =I8/H8-1 -> 0.04
A18: Asia Pacific & Latin America | D18: =D9/C9-1 -> -0.0012797952 | E18: =E9/D9-1 -> 0.02 | F18: =F9/E9-1 -> 0.04 | G18: =G9/F9-1 -> 0.05 | H18: =H9/G9-1 -> 0.05 | I18: =I9/H9-1 -> 0.05
A19: Converse | D19: =D10/C10-1 -> -0.30614657 | E19: =E10/D10-1 -> -0.1 | F19: =F10/E10-1 -> -0.03 | G19: =G10/F10-1 -> 0.02 | H19: =H10/G10-1 -> 0.02 | I19: =I10/H10-1 -> 0.02
A20: Total revenue growth | C20: =C12/B12-1 -> -0.098380125 | D20: =D12/C12-1 -> 0.0019218726 | E20: =E12/D12-1 -> 0.016961722 | F20: =F12/E12-1 -> 0.035483564 | G20: =G12/F12-1 -> 0.044341474 | H20: =H12/G12-1 -> 0.040913049 | I20: =I12/H12-1 -> 0.038245046
A22: Revenue mix
A23: North America | C23: =C6/C12 -> 0.42263923 | D23: =D6/D12 -> 0.44206647 | E23: =E6/E12 -> 0.45208105 | F23: =F6/F12 -> 0.45841877 | G23: =G6/G12 -> 0.46090261 | H23: =H6/H12 -> 0.46049833 | I23: =I6/I12 -> 0.46127671
A24: Europe, Middle East & Africa | C24: =C7/C12 -> 0.26467857 | D24: =D7/D12 -> 0.27095996 | E24: =E7/E12 -> 0.27176948 | F24: =F7/F12 -> 0.27033028 | G24: =G7/G12 -> 0.26920648 | H24: =H7/H12 -> 0.26897034 | I24: =I7/I12 -> 0.26683436
A25: Greater China | C25: =C8/C12 -> 0.14221858 | D25: =D8/D12 -> 0.12601836 | E25: =E8/E12 -> 0.1177207 | F25: =F8/F12 -> 0.11368669 | G25: =G8/G12 -> 0.11212548 | H25: =H8/H12 -> 0.11202713 | I25: =I8/I12 -> 0.11221649
A26: Asia Pacific & Latin America | C26: =C9/C12 -> 0.13498456 | D26: =D9/D12 -> 0.13455321 | E26: =E9/E12 -> 0.13495521 | F26: =F9/F12 -> 0.13554383 | G26: =G9/G12 -> 0.13627825 | H26: =H9/H12 -> 0.13746793 | I26: =I9/I12 -> 0.13902433
A27: Converse | C27: =C10/C12 -> 0.036537174 | D27: =D10/D12 -> 0.025302815 | E27: =E10/E12 -> 0.022392714 | F27: =F10/F12 -> 0.020976608 | G27: =G10/G12 -> 0.020487686 | H27: =H10/H12 -> 0.020076067 | I27: =I10/I12 -> 0.019723271

Sheet Income Statement
A1: Income Statement
A2: FY2024 to FY2026 as reported (10-K). FY2027 to FY2031 forecast from the Assumptions sheet.
A4: $ millions unless stated | B4: FY2024A | C4: FY2025A | D4: FY2026A | E4: FY2027E | F4: FY2028E | G4: FY2029E | H4: FY2030E | I4: FY2031E
A5: Revenues | B5: 51362 | C5: 46309 | D5: 46398 | E5: ='Revenue Build'!E12 -> 47184.99 | F5: ='Revenue Build'!F12 -> 48859.282 | G5: ='Revenue Build'!G12 -> 51025.774 | H5: ='Revenue Build'!H12 -> 53113.394 | I5: ='Revenue Build'!I12 -> 55144.718
A6: Cost of sales | B6: 28475 | C6: 26519 | D6: 26487 | E6: =E5*(1-Assumptions!E42) -> 26895.444 | F6: =F5*(1-Assumptions!F42) -> 27605.494 | G6: =G5*(1-Assumptions!G42) -> 28574.434 | H6: =H5*(1-Assumptions!H42) -> 29477.934 | I6: =I5*(1-Assumptions!I42) -> 30605.319
A7: Gross profit | B7: =B5-B6 -> 22887 | C7: =C5-C6 -> 19790 | D7: =D5-D6 -> 19911 | E7: =E5-E6 -> 20289.546 | F7: =F5-F6 -> 21253.787 | G7: =G5-G6 -> 22451.341 | H7: =H5-H6 -> 23635.46 | I7: =I5-I6 -> 24539.4
A8: Demand creation expense | B8: 4285 | C8: 4689 | D8: 4754 | E8: =E5*Assumptions!E43 -> 4718.499 | F8: =F5*Assumptions!F43 -> 4788.2096 | G8: =G5*Assumptions!G43 -> 4898.4743 | H8: =H5*Assumptions!H43 -> 5045.7724 | I8: =I5*Assumptions!I43 -> 5238.7482
A9: Operating overhead expense | B9: 12291 | C9: 11399 | D9: 11360 | E9: =E5*Assumptions!E44 -> 11465.953 | F9: =F5*Assumptions!F44 -> 11726.228 | G9: =G5*Assumptions!G44 -> 12093.108 | H9: =H5*Assumptions!H44 -> 12481.648 | I9: =I5*Assumptions!I44 -> 12848.719
A10: Operating income (EBIT) | B10: =B7-B8-B9 -> 6311 | C10: =C7-C8-C9 -> 3702 | D10: =D7-D8-D9 -> 3797 | E10: =E7-E8-E9 -> 4105.0941 | F10: =F7-F8-F9 -> 4739.3503 | G10: =G7-G8-G9 -> 5459.7578 | H10: =H7-H8-H9 -> 6108.0403 | I10: =I7-I8-I9 -> 6451.9321
A11: Interest expense (income), net | B11: -161 | C11: -107 | D11: -50 | E11: =Assumptions!E51*('Balance Sheet'!D19+'Balance Sheet'!D25)-Assumptions!E52*('Balance Sheet'!D6+'Balance Sheet'!D7) -> 1.735 | F11: =Assumptions!F51*('Balance Sheet'!E19+'Balance Sheet'!E25)-Assumptions!F52*('Balance Sheet'!E6+'Balance Sheet'!E7) -> -44.51136 | G11: =Assumptions!G51*('Balance Sheet'!F19+'Balance Sheet'!F25)-Assumptions!G52*('Balance Sheet'!F6+'Balance Sheet'!F7) -> -53.587008 | H11: =Assumptions!H51*('Balance Sheet'!G19+'Balance Sheet'!G25)-Assumptions!H52*('Balance Sheet'!G6+'Balance Sheet'!G7) -> -63.429363 | I11: =Assumptions!I51*('Balance Sheet'!H19+'Balance Sheet'!H25)-Assumptions!I52*('Balance Sheet'!H6+'Balance Sheet'!H7) -> -61.543051 | J11: Forecast: opening debt x rate less opening cash x rate (avoids a circular reference)
A12: Other (income) expense, net | B12: -228 | C12: -76 | D12: -53 | E12: 0 | F12: 0 | G12: 0 | H12: 0 | I12: 0 | J12: Forecast: assumed nil
A13: Income before income taxes | B13: =B10-B11-B12 -> 6700 | C13: =C10-C11-C12 -> 3885 | D13: =D10-D11-D12 -> 3900 | E13: =E10-E11-E12 -> 4103.3591 | F13: =F10-F11-F12 -> 4783.8617 | G13: =G10-G11-G12 -> 5513.3448 | H13: =H10-H11-H12 -> 6171.4697 | I13: =I10-I11-I12 -> 6513.4751
A14: Income tax expense | B14: 1000 | C14: 666 | D14: 792 | E14: =E13*Assumptions!E50 -> 779.63823 | F14: =F13*Assumptions!F50 -> 908.93372 | G14: =G13*Assumptions!G50 -> 1047.5355 | H14: =H13*Assumptions!H50 -> 1172.5792 | I14: =I13*Assumptions!I50 -> 1237.5603
A15: Net income | B15: =B13-B14 -> 5700 | C15: =C13-C14 -> 3219 | D15: =D13-D14 -> 3108 | E15: =E13-E14 -> 3323.7209 | F15: =F13-F14 -> 3874.928 | G15: =G13-G14 -> 4465.8093 | H15: =H13-H14 -> 4998.8905 | I15: =I13-I14 -> 5275.9148
A17: Diluted shares (m) | B17: 1529.7 | C17: 1487.6 | D17: 1481 | E17: =D17-Assumptions!E64/Assumptions!E65+Assumptions!E66 -> 1475.6667 | F17: =E17-Assumptions!F64/Assumptions!F65+Assumptions!F66 -> 1457 | G17: =F17-Assumptions!G64/Assumptions!G65+Assumptions!G66 -> 1431.6667 | H17: =G17-Assumptions!H64/Assumptions!H65+Assumptions!H66 -> 1399.6667 | I17: =H17-Assumptions!I64/Assumptions!I65+Assumptions!I66 -> 1361
A18: Diluted EPS ($) | B18: =B15/B17 -> 3.7262208 | C18: =C15/C17 -> 2.1638881 | D18: =D15/D17 -> 2.098582 | E18: =E15/E17 -> 2.2523521 | F18: =F15/F17 -> 2.659525 | G18: =G15/G17 -> 3.119308 | H18: =H15/H17 -> 3.5714864 | I18: =I15/I17 -> 3.8764988
A19: Dividends per share ($) | B19: =-'Cash Flow'!B24/B17 -> 1.4179251 | C19: =-'Cash Flow'!C24/C17 -> 1.5461145 | D19: =-'Cash Flow'!D24/D17 -> 1.6252532 | E19: =D19*(1+Assumptions!E63) -> 1.7065159 | F19: =E19*(1+Assumptions!F63) -> 1.7918417 | G19: =F19*(1+Assumptions!G63) -> 1.8814337 | H19: =G19*(1+Assumptions!H63) -> 1.9755054 | I19: =H19*(1+Assumptions!I63) -> 2.0742807
A21: Margins
A22: Gross margin | B22: =B7/B5 -> 0.44560181 | C22: =C7/C5 -> 0.42734674 | D22: =D7/D5 -> 0.42913488 | E22: =E7/E5 -> 0.43 | F22: =F7/F5 -> 0.435 | G22: =G7/G5 -> 0.44 | H22: =H7/H5 -> 0.445 | I22: =I7/I5 -> 0.445
A23: Demand creation % of revenue | B23: =B8/B5 -> 0.083427437 | C23: =C8/C5 -> 0.10125462 | D23: =D8/D5 -> 0.10246131 | E23: =E8/E5 -> 0.1 | F23: =F8/F5 -> 0.098 | G23: =G8/G5 -> 0.096 | H23: =H8/H5 -> 0.095 | I23: =I8/I5 -> 0.095
A24: Operating overhead % of revenue | B24: =B9/B5 -> 0.23930143 | C24: =C9/C5 -> 0.24615086 | D24: =D9/D5 -> 0.24483814 | E24: =E9/E5 -> 0.243 | F24: =F9/F5 -> 0.24 | G24: =G9/G5 -> 0.237 | H24: =H9/H5 -> 0.235 | I24: =I9/I5 -> 0.233
A25: EBIT margin | B25: =B10/B5 -> 0.12287294 | C25: =C10/C5 -> 0.079941264 | D25: =D10/D5 -> 0.081835424 | E25: =E10/E5 -> 0.087 | F25: =F10/F5 -> 0.097 | G25: =G10/G5 -> 0.107 | H25: =H10/H5 -> 0.115 | I25: =I10/I5 -> 0.117
A26: Net margin | B26: =B15/B5 -> 0.11097699 | C26: =C15/C5 -> 0.069511326 | D26: =D15/D5 -> 0.066985646 | E26: =E15/E5 -> 0.070440216 | F26: =F15/F5 -> 0.079307919 | G26: =G15/G5 -> 0.087520658 | H26: =H15/H5 -> 0.094117323 | I26: =I15/I5 -> 0.095673983
A27: Effective tax rate | B27: =B14/B13 -> 0.14925373 | C27: =C14/C13 -> 0.17142857 | D27: =D14/D13 -> 0.20307692 | E27: =E14/E13 -> 0.19 | F27: =F14/F13 -> 0.19 | G27: =G14/G13 -> 0.19 | H27: =H14/H13 -> 0.19 | I27: =I14/I13 -> 0.19

Sheet Balance Sheet
A1: Balance Sheet
A2: Balances at 31 May. History from the 10-K (intangibles and goodwill combined; notes payable in short-term debt). Cash is the balancing figure from the cash flow.
A4: $ millions unless stated | B4: FY2024A | C4: FY2025A | D4: FY2026A | E4: FY2027E | F4: FY2028E | G4: FY2029E | H4: FY2030E | I4: FY2031E
A5: Assets
A6: Cash and equivalents | B6: 9860 | C6: 7464 | D6: 7563 | E6: ='Cash Flow'!E32 -> 6598.6103 | F6: ='Cash Flow'!F32 -> 6857.9145 | G6: ='Cash Flow'!G32 -> 7139.1247 | H6: ='Cash Flow'!H32 -> 7085.23 | I6: ='Cash Flow'!I32 -> 6676.2786
A7: Short-term investments | B7: 1722 | C7: 1687 | D7: 1464 | E7: =D7 -> 1464 | F7: =E7 -> 1464 | G7: =F7 -> 1464 | H7: =G7 -> 1464 | I7: =H7 -> 1464
A8: Accounts receivable, net | B8: 4427 | C8: 4717 | D8: 5931 | E8: ='Income Statement'!E5*Assumptions!E55/365 -> 5688.0536 | F8: ='Income Statement'!F5*Assumptions!F55/365 -> 5622.1639 | G8: ='Income Statement'!G5*Assumptions!G55/365 -> 5591.8657 | H8: ='Income Statement'!H5*Assumptions!H55/365 -> 5820.6459 | I8: ='Income Statement'!I5*Assumptions!I55/365 -> 6043.2568
A9: Inventories | B9: 7519 | C9: 7489 | D9: 7501 | E9: ='Income Statement'!E6*Assumptions!E56/365 -> 7368.6149 | F9: ='Income Statement'!F6*Assumptions!F56/365 -> 7411.8861 | G9: ='Income Statement'!G6*Assumptions!G56/365 -> 7515.4675 | H9: ='Income Statement'!H6*Assumptions!H56/365 -> 7672.3389 | I9: ='Income Statement'!I6*Assumptions!I56/365 -> 7965.7679
A10: Prepaid expenses and other current assets | B10: 1854 | C10: 2005 | D10: 2144 | E10: ='Income Statement'!E5*Assumptions!E58 -> 2170.5095 | F10: ='Income Statement'!F5*Assumptions!F58 -> 2247.527 | G10: ='Income Statement'!G5*Assumptions!G58 -> 2347.1856 | H10: ='Income Statement'!H5*Assumptions!H58 -> 2443.2161 | I10: ='Income Statement'!I5*Assumptions!I58 -> 2536.657
A11: Total current assets | B11: =SUM(B6:B10) -> 25382 | C11: =SUM(C6:C10) -> 23362 | D11: =SUM(D6:D10) -> 24603 | E11: =SUM(E6:E10) -> 23289.788 | F11: =SUM(F6:F10) -> 23603.491 | G11: =SUM(G6:G10) -> 24057.643 | H11: =SUM(H6:H10) -> 24485.431 | I11: =SUM(I6:I10) -> 24685.96
A12: Property, plant and equipment, net | B12: 5000 | C12: 4828 | D12: 4796 | E12: =D12-'Cash Flow'!E18-'Cash Flow'!E7 -> 4796 | F12: =E12-'Cash Flow'!F18-'Cash Flow'!F7 -> 4796 | G12: =F12-'Cash Flow'!G18-'Cash Flow'!G7 -> 4796 | H12: =G12-'Cash Flow'!H18-'Cash Flow'!H7 -> 4796 | I12: =H12-'Cash Flow'!I18-'Cash Flow'!I7 -> 4796
A13: Operating lease right-of-use assets | B13: 2718 | C13: 2712 | D13: 2838 | E13: =D13 -> 2838 | F13: =E13 -> 2838 | G13: =F13 -> 2838 | H13: =G13 -> 2838 | I13: =H13 -> 2838
A14: Intangible assets and goodwill | B14: 499 | C14: 499 | D14: 499 | E14: =D14 -> 499 | F14: =E14 -> 499 | G14: =F14 -> 499 | H14: =G14 -> 499 | I14: =H14 -> 499
A15: Deferred income taxes and other assets | B15: 4511 | C15: 5178 | D15: 5674 | E15: =D15 -> 5674 | F15: =E15 -> 5674 | G15: =F15 -> 5674 | H15: =G15 -> 5674 | I15: =H15 -> 5674
A16: Total assets | B16: =B11+SUM(B12:B15) -> 38110 | C16: =C11+SUM(C12:C15) -> 36579 | D16: =D11+SUM(D12:D15) -> 38410 | E16: =E11+SUM(E12:E15) -> 37096.788 | F16: =F11+SUM(F12:F15) -> 37410.491 | G16: =G11+SUM(G12:G15) -> 37864.643 | H16: =H11+SUM(H12:H15) -> 38292.431 | I16: =I11+SUM(I12:I15) -> 38492.96
A18: Liabilities
A19: Short-term debt and current portion of long-term debt | B19: 1006 | C19: 5 | D19: 2000 | E19: =MAX(D19-Assumptions!E62,0) -> 0 | F19: =MAX(E19-Assumptions!F62,0) -> 0 | G19: =MAX(F19-Assumptions!G62,0) -> 0 | H19: =MAX(G19-Assumptions!H62,0) -> 0 | I19: =MAX(H19-Assumptions!I62,0) -> 0
A20: Accounts payable | B20: 2851 | C20: 3479 | D20: 3600 | E20: ='Income Statement'!E6*Assumptions!E57/365 -> 3684.3074 | F20: ='Income Statement'!F6*Assumptions!F57/365 -> 3781.5745 | G20: ='Income Statement'!G6*Assumptions!G57/365 -> 3914.306 | H20: ='Income Statement'!H6*Assumptions!H57/365 -> 4038.0731 | I20: ='Income Statement'!I6*Assumptions!I57/365 -> 4192.5094
A21: Accrued liabilities | B21: 5725 | C21: 5911 | D21: 6092 | E21: ='Income Statement'!E5*Assumptions!E59 -> 6181.2337 | F21: ='Income Statement'!F5*Assumptions!F59 -> 6400.5659 | G21: ='Income Statement'!G5*Assumptions!G59 -> 6684.3764 | H21: ='Income Statement'!H5*Assumptions!H59 -> 6957.8546 | I21: ='Income Statement'!I5*Assumptions!I59 -> 7223.9581
A22: Income taxes payable | B22: 534 | C22: 669 | D22: 377 | E22: =D22 -> 377 | F22: =E22 -> 377 | G22: =F22 -> 377 | H22: =G22 -> 377 | I22: =H22 -> 377
A23: Current operating lease liabilities | B23: 477 | C23: 502 | D23: 478 | E23: =D23 -> 478 | F23: =E23 -> 478 | G23: =F23 -> 478 | H23: =G23 -> 478 | I23: =H23 -> 478
A24: Total current liabilities | B24: =SUM(B19:B23) -> 10593 | C24: =SUM(C19:C23) -> 10566 | D24: =SUM(D19:D23) -> 12547 | E24: =SUM(E19:E23) -> 10720.541 | F24: =SUM(F19:F23) -> 11037.14 | G24: =SUM(G19:G23) -> 11453.682 | H24: =SUM(H19:H23) -> 11850.928 | I24: =SUM(I19:I23) -> 12271.468
A25: Long-term debt | B25: 7903 | C25: 7961 | D25: 5942 | E25: =D25-MAX(Assumptions!E62-D19,0) -> 5942 | F25: =E25-MAX(Assumptions!F62-E19,0) -> 5942 | G25: =F25-MAX(Assumptions!G62-F19,0) -> 5942 | H25: =G25-MAX(Assumptions!H62-G19,0) -> 5942 | I25: =H25-MAX(Assumptions!I62-H19,0) -> 5942
A26: Operating lease liabilities | B26: 2566 | C26: 2550 | D26: 2613 | E26: =D26 -> 2613 | F26: =E26 -> 2613 | G26: =F26 -> 2613 | H26: =G26 -> 2613 | I26: =H26 -> 2613
A27: Deferred income taxes and other liabilities | B27: 2618 | C27: 2289 | D27: 2443 | E27: =D27 -> 2443 | F27: =E27 -> 2443 | G27: =F27 -> 2443 | H27: =G27 -> 2443 | I27: =H27 -> 2443
A28: Total liabilities | B28: =B24+SUM(B25:B27) -> 23680 | C28: =C24+SUM(C25:C27) -> 23366 | D28: =D24+SUM(D25:D27) -> 23545 | E28: =E24+SUM(E25:E27) -> 21718.541 | F28: =F24+SUM(F25:F27) -> 22035.14 | G28: =G24+SUM(G25:G27) -> 22451.682 | H28: =H24+SUM(H25:H27) -> 22848.928 | I28: =I24+SUM(I25:I27) -> 23269.468
A30: Shareholders' equity
A31: Common stock and capital in excess of stated value | B31: 13412 | C31: 14198 | D31: 15161 | E31: =D31+'Cash Flow'!E8 -> 15868.775 | F31: =E31+'Cash Flow'!F8 -> 16601.664 | G31: =F31+'Cash Flow'!G8 -> 17367.051 | H31: =G31+'Cash Flow'!H8 -> 18163.752 | I31: =H31+'Cash Flow'!I8 -> 18990.922
A32: Accumulated other comprehensive income (loss) | B32: 53 | C32: -258 | D32: -141 | E32: =D32 -> -141 | F32: =E32 -> -141 | G32: =F32 -> -141 | H32: =G32 -> -141 | I32: =H32 -> -141
A33: Retained earnings (deficit) | B33: 965 | C33: -727 | D33: -155 | E33: =D33+'Income Statement'!E15+'Cash Flow'!E24+'Cash Flow'!E25 -> -349.52769 | F33: =E33+'Income Statement'!F15+'Cash Flow'!F24+'Cash Flow'!F25 -> -1085.313 | G33: =F33+'Income Statement'!G15+'Cash Flow'!G24+'Cash Flow'!G25 -> -1813.0897 | H33: =G33+'Income Statement'!H15+'Cash Flow'!H24+'Cash Flow'!H25 -> -2579.2483 | I33: =H33+'Income Statement'!I15+'Cash Flow'!I24+'Cash Flow'!I25 -> -3626.4295
A34: Total shareholders' equity | B34: =SUM(B31:B33) -> 14430 | C34: =SUM(C31:C33) -> 13213 | D34: =SUM(D31:D33) -> 14865 | E34: =SUM(E31:E33) -> 15378.247 | F34: =SUM(F31:F33) -> 15375.351 | G34: =SUM(G31:G33) -> 15412.961 | H34: =SUM(H31:H33) -> 15443.503 | I34: =SUM(I31:I33) -> 15223.493
A35: Total liabilities and shareholders' equity | B35: =B28+B34 -> 38110 | C35: =C28+C34 -> 36579 | D35: =D28+D34 -> 38410 | E35: =E28+E34 -> 37096.788 | F35: =F28+F34 -> 37410.491 | G35: =G28+G34 -> 37864.643 | H35: =H28+H34 -> 38292.431 | I35: =I28+I34 -> 38492.96
A37: Check: assets - liabilities - equity (should be 0) | B37: =ROUND(B16-B35,0) -> 0 | C37: =ROUND(C16-C35,0) -> 0 | D37: =ROUND(D16-D35,0) -> 0 | E37: =ROUND(E16-E35,0) -> 0 | F37: =ROUND(F16-F35,0) -> 0 | G37: =ROUND(G16-G35,0) -> 0 | H37: =ROUND(H16-H35,0) -> 0 | I37: =ROUND(I16-I35,0) -> 0

Sheet Cash Flow
A1: Cash Flow Statement
A2: History from the 10-K (smaller items grouped). Forecast built from the income statement and balance sheet movements.
A4: $ millions unless stated | B4: FY2024A | C4: FY2025A | D4: FY2026A | E4: FY2027E | F4: FY2028E | G4: FY2029E | H4: FY2030E | I4: FY2031E
A5: Operating activities
A6: Net income | B6: ='Income Statement'!B15 -> 5700 | C6: ='Income Statement'!C15 -> 3219 | D6: ='Income Statement'!D15 -> 3108 | E6: ='Income Statement'!E15 -> 3323.7209 | F6: ='Income Statement'!F15 -> 3874.928 | G6: ='Income Statement'!G15 -> 4465.8093 | H6: ='Income Statement'!H15 -> 4998.8905 | I6: ='Income Statement'!I15 -> 5275.9148
A7: Depreciation and amortization | B7: 796 | C7: 775 | D7: 747 | E7: ='Income Statement'!E5*Assumptions!E45 -> 754.95984 | F7: ='Income Statement'!F5*Assumptions!F45 -> 781.74851 | G7: ='Income Statement'!G5*Assumptions!G45 -> 816.41239 | H7: ='Income Statement'!H5*Assumptions!H45 -> 849.81431 | I7: ='Income Statement'!I5*Assumptions!I45 -> 882.31549
A8: Stock-based compensation | B8: 804 | C8: 709 | D8: 715 | E8: ='Income Statement'!E5*Assumptions!E46 -> 707.77485 | F8: ='Income Statement'!F5*Assumptions!F46 -> 732.88922 | G8: ='Income Statement'!G5*Assumptions!G46 -> 765.38661 | H8: ='Income Statement'!H5*Assumptions!H46 -> 796.70091 | I8: ='Income Statement'!I5*Assumptions!I46 -> 827.17078
A9: (Increase) decrease in receivables | E9: ='Balance Sheet'!D8-'Balance Sheet'!E8 -> 242.94641 | F9: ='Balance Sheet'!E8-'Balance Sheet'!F8 -> 65.889679 | G9: ='Balance Sheet'!F8-'Balance Sheet'!G8 -> 30.298246 | H9: ='Balance Sheet'!G8-'Balance Sheet'!H8 -> -228.78027 | I9: ='Balance Sheet'!H8-'Balance Sheet'!I8 -> -222.61087
A10: (Increase) decrease in inventories | E10: ='Balance Sheet'!D9-'Balance Sheet'!E9 -> 132.38512 | F10: ='Balance Sheet'!E9-'Balance Sheet'!F9 -> -43.271211 | G10: ='Balance Sheet'!F9-'Balance Sheet'!G9 -> -103.58136 | H10: ='Balance Sheet'!G9-'Balance Sheet'!H9 -> -156.87147 | I10: ='Balance Sheet'!H9-'Balance Sheet'!I9 -> -293.42896
A11: (Increase) decrease in prepaid and other | E11: ='Balance Sheet'!D10-'Balance Sheet'!E10 -> -26.50954 | F11: ='Balance Sheet'!E10-'Balance Sheet'!F10 -> -77.017414 | G11: ='Balance Sheet'!F10-'Balance Sheet'!G10 -> -99.658659 | H11: ='Balance Sheet'!G10-'Balance Sheet'!H10 -> -96.03052 | I11: ='Balance Sheet'!H10-'Balance Sheet'!I10 -> -93.440914
A12: Increase (decrease) in payables | E12: ='Balance Sheet'!E20-'Balance Sheet'!D20 -> 84.307438 | F12: ='Balance Sheet'!F20-'Balance Sheet'!E20 -> 97.267096 | G12: ='Balance Sheet'!G20-'Balance Sheet'!F20 -> 132.73143 | H12: ='Balance Sheet'!H20-'Balance Sheet'!G20 -> 123.76715 | I12: ='Balance Sheet'!I20-'Balance Sheet'!H20 -> 154.43629
A13: Increase (decrease) in accrued liabilities | E13: ='Balance Sheet'!E21-'Balance Sheet'!D21 -> 89.23369 | F13: ='Balance Sheet'!F21-'Balance Sheet'!E21 -> 219.3322 | G13: ='Balance Sheet'!G21-'Balance Sheet'!F21 -> 283.81053 | H13: ='Balance Sheet'!H21-'Balance Sheet'!G21 -> 273.47822 | I13: ='Balance Sheet'!I21-'Balance Sheet'!H21 -> 266.10347
A14: Working capital and other items (history, total) | B14: =7429-B6-B7-B8 -> 129 | C14: =3698-C6-C7-C8 -> -1005 | D14: =2868-D6-D7-D8 -> -1702 | E14: 0 | F14: 0 | G14: 0 | H14: 0 | I14: 0
A15: Cash provided by operations | B15: =SUM(B6:B14) -> 7429 | C15: =SUM(C6:C14) -> 3698 | D15: =SUM(D6:D14) -> 2868 | E15: =SUM(E6:E14) -> 5308.8187 | F15: =SUM(F6:F14) -> 5651.766 | G15: =SUM(G6:G14) -> 6291.2085 | H15: =SUM(H6:H14) -> 6560.9688 | I15: =SUM(I6:I14) -> 6796.4601
A17: Investing activities
A18: Additions to property, plant and equipment | B18: -812 | C18: -430 | D18: -684 | E18: =-'Income Statement'!E5*Assumptions!E47 -> -754.95984 | F18: =-'Income Statement'!F5*Assumptions!F47 -> -781.74851 | G18: =-'Income Statement'!G5*Assumptions!G47 -> -816.41239 | H18: =-'Income Statement'!H5*Assumptions!H47 -> -849.81431 | I18: =-'Income Statement'!I5*Assumptions!I47 -> -882.31549
A19: Short-term investments and other | B19: =894-B18 -> 1706 | C19: =-275-C18 -> 155 | D19: =-488-D18 -> 196 | E19: 0 | F19: 0 | G19: 0 | H19: 0 | I19: 0
A20: Cash used by investing activities | B20: =B18+B19 -> 894 | C20: =C18+C19 -> -275 | D20: =D18+D19 -> -488 | E20: =E18+E19 -> -754.95984 | F20: =F18+F19 -> -781.74851 | G20: =G18+G19 -> -816.41239 | H20: =H18+H19 -> -849.81431 | I20: =I18+I19 -> -882.31549
A22: Financing activities
A23: Debt repaid | B23: 0 | C23: -1001 | D23: 0 | E23: =-Assumptions!E62 -> -2000 | F23: =-Assumptions!F62 -> 0 | G23: =-Assumptions!G62 -> 0 | H23: =-Assumptions!H62 -> 0 | I23: =-Assumptions!I62 -> 0
A24: Dividends paid | B24: -2169 | C24: -2300 | D24: -2407 | E24: =-'Income Statement'!E19*'Income Statement'!E17 -> -2518.2486 | F24: =-'Income Statement'!F19*'Income Statement'!F17 -> -2610.7133 | G24: =-'Income Statement'!G19*'Income Statement'!G17 -> -2693.586 | H24: =-'Income Statement'!H19*'Income Statement'!H17 -> -2765.0491 | I24: =-'Income Statement'!I19*'Income Statement'!I17 -> -2823.096
A25: Share buybacks | B25: -4250 | C25: -2985 | D25: -146 | E25: =-Assumptions!E64 -> -1000 | F25: =-Assumptions!F64 -> -2000 | G25: =-Assumptions!G64 -> -2500 | H25: =-Assumptions!H64 -> -3000 | I25: =-Assumptions!I64 -> -3500
A26: Share issuance and other | B26: =-5888-B23-B24-B25 -> 531 | C26: =-5820-C23-C24-C25 -> 466 | D26: =-2292-D23-D24-D25 -> 261 | E26: 0 | F26: 0 | G26: 0 | H26: 0 | I26: 0
A27: Cash used by financing activities | B27: =SUM(B23:B26) -> -5888 | C27: =SUM(C23:C26) -> -5820 | D27: =SUM(D23:D26) -> -2292 | E27: =SUM(E23:E26) -> -5518.2486 | F27: =SUM(F23:F26) -> -4610.7133 | G27: =SUM(G23:G26) -> -5193.586 | H27: =SUM(H23:H26) -> -5765.0491 | I27: =SUM(I23:I26) -> -6323.096
A29: Effect of exchange rates | B29: -16 | C29: 1 | D29: 11 | E29: 0 | F29: 0 | G29: 0 | H29: 0 | I29: 0
A30: Net change in cash | B30: =B15+B20+B27+B29 -> 2419 | C30: =C15+C20+C27+C29 -> -2396 | D30: =D15+D20+D27+D29 -> 99 | E30: =E15+E20+E27+E29 -> -964.38971 | F30: =F15+F20+F27+F29 -> 259.30423 | G30: =G15+G20+G27+G29 -> 281.21014 | H30: =H15+H20+H27+H29 -> -53.89463 | I30: =I15+I20+I27+I29 -> -408.9514
A31: Cash at beginning of year | B31: 7441 | C31: 9860 | D31: 7464 | E31: =D32 -> 7563 | F31: =E32 -> 6598.6103 | G31: =F32 -> 6857.9145 | H31: =G32 -> 7139.1247 | I31: =H32 -> 7085.23
A32: Cash at end of year | B32: =B31+B30 -> 9860 | C32: =C31+C30 -> 7464 | D32: =D31+D30 -> 7563 | E32: =E31+E30 -> 6598.6103 | F32: =F31+F30 -> 6857.9145 | G32: =G31+G30 -> 7139.1247 | H32: =H31+H30 -> 7085.23 | I32: =I31+I30 -> 6676.2786
A34: Free cash flow
A35: Free cash flow (operations less capex) | B35: =B15+B18 -> 6617 | C35: =C15+C18 -> 3268 | D35: =D15+D18 -> 2184 | E35: =E15+E18 -> 4553.8589 | F35: =F15+F18 -> 4870.0175 | G35: =G15+G18 -> 5474.7961 | H35: =H15+H18 -> 5711.1545 | I35: =I15+I18 -> 5914.1446
A36: Cash returned to shareholders | B36: =-B24-B25 -> 6419 | C36: =-C24-C25 -> 5285 | D36: =-D24-D25 -> 2553 | E36: =-E24-E25 -> 3518.2486 | F36: =-F24-F25 -> 4610.7133 | G36: =-G24-G25 -> 5193.586 | H36: =-H24-H25 -> 5765.0491 | I36: =-I24-I25 -> 6323.096

Sheet Scenarios
A1: Scenario Comparison
A2: Revenue and operating income under each scenario, calculated in parallel (independent of the scenario selector).
A4: $ millions unless stated | B4: FY2024A | C4: FY2025A | D4: FY2026A | E4: FY2027E | F4: FY2028E | G4: FY2029E | H4: FY2030E | I4: FY2031E
A5: Base case
A6: North America | C6: ='Revenue Build'!C6 -> 19572 | D6: ='Revenue Build'!D6 -> 20511 | E6: =D6*(1+Assumptions!E16) -> 21331.44 | F6: =E6*(1+Assumptions!F16) -> 22398.012 | G6: =F6*(1+Assumptions!G16) -> 23517.913 | H6: =G6*(1+Assumptions!H16) -> 24458.629 | I6: =H6*(1+Assumptions!I16) -> 25436.974
A7: Europe, Middle East & Africa | C7: ='Revenue Build'!C7 -> 12257 | D7: ='Revenue Build'!D7 -> 12572 | E7: =D7*(1+Assumptions!E17) -> 12823.44 | F7: =E7*(1+Assumptions!F17) -> 13208.143 | G7: =F7*(1+Assumptions!G17) -> 13736.469 | H7: =G7*(1+Assumptions!H17) -> 14285.928 | I7: =H7*(1+Assumptions!I17) -> 14714.506
A8: Greater China | C8: ='Revenue Build'!C8 -> 6586 | D8: ='Revenue Build'!D8 -> 5847 | E8: =D8*(1+Assumptions!E18) -> 5554.65 | F8: =E8*(1+Assumptions!F18) -> 5554.65 | G8: =F8*(1+Assumptions!G18) -> 5721.2895 | H8: =G8*(1+Assumptions!H18) -> 5950.1411 | I8: =H8*(1+Assumptions!I18) -> 6188.1467
A9: Asia Pacific & Latin America | C9: ='Revenue Build'!C9 -> 6251 | D9: ='Revenue Build'!D9 -> 6243 | E9: =D9*(1+Assumptions!E19) -> 6367.86 | F9: =E9*(1+Assumptions!F19) -> 6622.5744 | G9: =F9*(1+Assumptions!G19) -> 6953.7031 | H9: =G9*(1+Assumptions!H19) -> 7301.3883 | I9: =H9*(1+Assumptions!I19) -> 7666.4577
A10: Converse | C10: ='Revenue Build'!C10 -> 1692 | D10: ='Revenue Build'!D10 -> 1174 | E10: =D10*(1+Assumptions!E20) -> 1056.6 | F10: =E10*(1+Assumptions!F20) -> 1024.902 | G10: =F10*(1+Assumptions!G20) -> 1045.4 | H10: =G10*(1+Assumptions!H20) -> 1066.308 | I10: =H10*(1+Assumptions!I20) -> 1087.6342
A11: Total revenue | D11: ='Revenue Build'!D12 -> 46398 | E11: =SUM(E6:E10)+Assumptions!E36 -> 47184.99 | F11: =SUM(F6:F10)+Assumptions!F36 -> 48859.282 | G11: =SUM(G6:G10)+Assumptions!G36 -> 51025.774 | H11: =SUM(H6:H10)+Assumptions!H36 -> 53113.394 | I11: =SUM(I6:I10)+Assumptions!I36 -> 55144.718 | K11: Base case
A12: Operating income (EBIT) | D12: ='Income Statement'!D10 -> 3797 | E12: =E11*(Assumptions!E39-Assumptions!E43-Assumptions!E44) -> 4105.0941 | F12: =F11*(Assumptions!F39-Assumptions!F43-Assumptions!F44) -> 4739.3503 | G12: =G11*(Assumptions!G39-Assumptions!G43-Assumptions!G44) -> 5459.7578 | H12: =H11*(Assumptions!H39-Assumptions!H43-Assumptions!H44) -> 6108.0403 | I12: =I11*(Assumptions!I39-Assumptions!I43-Assumptions!I44) -> 6451.9321
A13: EBIT margin | D13: =D12/D11 -> 0.081835424 | E13: =E12/E11 -> 0.087 | F13: =F12/F11 -> 0.097 | G13: =G12/G11 -> 0.107 | H13: =H12/H11 -> 0.115 | I13: =I12/I11 -> 0.117
A15: Upside case
A16: North America | C16: ='Revenue Build'!C6 -> 19572 | D16: ='Revenue Build'!D6 -> 20511 | E16: =D16*(1+Assumptions!E23) -> 21741.66 | F16: =E16*(1+Assumptions!F23) -> 23263.576 | G16: =F16*(1+Assumptions!G23) -> 24892.027 | H16: =G16*(1+Assumptions!H23) -> 26385.548 | I16: =H16*(1+Assumptions!I23) -> 27704.826
A17: Europe, Middle East & Africa | C17: ='Revenue Build'!C7 -> 12257 | D17: ='Revenue Build'!D7 -> 12572 | E17: =D17*(1+Assumptions!E24) -> 13074.88 | F17: =E17*(1+Assumptions!F24) -> 13728.624 | G17: =F17*(1+Assumptions!G24) -> 14552.341 | H17: =G17*(1+Assumptions!H24) -> 15279.959 | I17: =H17*(1+Assumptions!I24) -> 15891.157
A18: Greater China | C18: ='Revenue Build'!C8 -> 6586 | D18: ='Revenue Build'!D8 -> 5847 | E18: =D18*(1+Assumptions!E25) -> 5847 | F18: =E18*(1+Assumptions!F25) -> 6139.35 | G18: =F18*(1+Assumptions!G25) -> 6507.711 | H18: =G18*(1+Assumptions!H25) -> 6898.1737 | I18: =H18*(1+Assumptions!I25) -> 7243.0823
A19: Asia Pacific & Latin America | C19: ='Revenue Build'!C9 -> 6251 | D19: ='Revenue Build'!D9 -> 6243 | E19: =D19*(1+Assumptions!E26) -> 6492.72 | F19: =E19*(1+Assumptions!F26) -> 6882.2832 | G19: =F19*(1+Assumptions!G26) -> 7364.043 | H19: =G19*(1+Assumptions!H26) -> 7879.526 | I19: =H19*(1+Assumptions!I26) -> 8352.2976
A20: Converse | C20: ='Revenue Build'!C10 -> 1692 | D20: ='Revenue Build'!D10 -> 1174 | E20: =D20*(1+Assumptions!E27) -> 1115.3 | F20: =E20*(1+Assumptions!F27) -> 1137.606 | G20: =F20*(1+Assumptions!G27) -> 1183.1102 | H20: =G20*(1+Assumptions!H27) -> 1230.4346 | I20: =H20*(1+Assumptions!I27) -> 1267.3477
A21: Total revenue | D21: ='Revenue Build'!D12 -> 46398 | E21: =SUM(E16:E20)+Assumptions!E36 -> 48322.56 | F21: =SUM(F16:F20)+Assumptions!F36 -> 51202.439 | G21: =SUM(G16:G20)+Assumptions!G36 -> 54550.232 | H21: =SUM(H16:H20)+Assumptions!H36 -> 57724.641 | I21: =SUM(I16:I20)+Assumptions!I36 -> 60509.71 | K21: Upside case
A22: Operating income (EBIT) | D22: ='Income Statement'!D10 -> 3797 | E22: =E21*(Assumptions!E40-Assumptions!E43-Assumptions!E44) -> 4445.6755 | F22: =F21*(Assumptions!F40-Assumptions!F43-Assumptions!F44) -> 5478.661 | G22: =G21*(Assumptions!G40-Assumptions!G43-Assumptions!G44) -> 6655.1283 | H22: =H21*(Assumptions!H40-Assumptions!H43-Assumptions!H44) -> 7504.2033 | I22: =I21*(Assumptions!I40-Assumptions!I43-Assumptions!I44) -> 7987.2817
A23: EBIT margin | D23: =D22/D21 -> 0.081835424 | E23: =E22/E21 -> 0.092 | F23: =F22/F21 -> 0.107 | G23: =G22/G21 -> 0.122 | H23: =H22/H21 -> 0.13 | I23: =I22/I21 -> 0.132
A25: Downside case
A26: North America | C26: ='Revenue Build'!C6 -> 19572 | D26: ='Revenue Build'!D6 -> 20511 | E26: =D26*(1+Assumptions!E30) -> 20716.11 | F26: =E26*(1+Assumptions!F30) -> 21130.432 | G26: =F26*(1+Assumptions!G30) -> 21553.041 | H26: =G26*(1+Assumptions!H30) -> 21984.102 | I26: =H26*(1+Assumptions!I30) -> 22423.784
A27: Europe, Middle East & Africa | C27: ='Revenue Build'!C7 -> 12257 | D27: ='Revenue Build'!D7 -> 12572 | E27: =D27*(1+Assumptions!E31) -> 12320.56 | F27: =E27*(1+Assumptions!F31) -> 12320.56 | G27: =F27*(1+Assumptions!G31) -> 12443.766 | H27: =G27*(1+Assumptions!H31) -> 12692.641 | I27: =H27*(1+Assumptions!I31) -> 12946.494
A28: Greater China | C28: ='Revenue Build'!C8 -> 6586 | D28: ='Revenue Build'!D8 -> 5847 | E28: =D28*(1+Assumptions!E32) -> 5145.36 | F28: =E28*(1+Assumptions!F32) -> 4836.6384 | G28: =F28*(1+Assumptions!G32) -> 4739.9056 | H28: =G28*(1+Assumptions!H32) -> 4739.9056 | I28: =H28*(1+Assumptions!I32) -> 4787.3047
A29: Asia Pacific & Latin America | C29: ='Revenue Build'!C9 -> 6251 | D29: ='Revenue Build'!D9 -> 6243 | E29: =D29*(1+Assumptions!E33) -> 6180.57 | F29: =E29*(1+Assumptions!F33) -> 6242.3757 | G29: =F29*(1+Assumptions!G33) -> 6367.2232 | H29: =G29*(1+Assumptions!H33) -> 6558.2399 | I29: =H29*(1+Assumptions!I33) -> 6754.9871
A30: Converse | C30: ='Revenue Build'!C10 -> 1692 | D30: ='Revenue Build'!D10 -> 1174 | E30: =D30*(1+Assumptions!E34) -> 962.68 | F30: =E30*(1+Assumptions!F34) -> 885.6656 | G30: =F30*(1+Assumptions!G34) -> 859.09563 | H30: =G30*(1+Assumptions!H34) -> 859.09563 | I30: =H30*(1+Assumptions!I34) -> 859.09563
A31: Total revenue | D31: ='Revenue Build'!D12 -> 46398 | E31: =SUM(E26:E30)+Assumptions!E36 -> 45376.28 | F31: =SUM(F26:F30)+Assumptions!F36 -> 45466.672 | G31: =SUM(G26:G30)+Assumptions!G36 -> 46014.031 | H31: =SUM(H26:H30)+Assumptions!H36 -> 46884.984 | I31: =SUM(I26:I30)+Assumptions!I36 -> 47822.665 | K31: Downside case
A32: Operating income (EBIT) | D32: ='Income Statement'!D10 -> 3797 | E32: =E31*(Assumptions!E41-Assumptions!E43-Assumptions!E44) -> 3720.855 | F32: =F31*(Assumptions!F41-Assumptions!F43-Assumptions!F44) -> 3955.6005 | G32: =G31*(Assumptions!G41-Assumptions!G43-Assumptions!G44) -> 4371.3329 | H32: =H31*(Assumptions!H41-Assumptions!H43-Assumptions!H44) -> 4688.4984 | I32: =I31*(Assumptions!I41-Assumptions!I43-Assumptions!I44) -> 4877.9118
A33: EBIT margin | D33: =D32/D31 -> 0.081835424 | E33: =E32/E31 -> 0.082 | F33: =F32/F31 -> 0.087 | G33: =G32/G31 -> 0.095 | H33: =H32/H31 -> 0.1 | I33: =I32/I31 -> 0.102
A35: Summary: FY2031
A36: Scenario | B36: FY2031 revenue | C36: Revenue CAGR FY26-31 | D36: FY2031 EBIT | E36: FY2031 EBIT margin | K36: Chart data
A37: Base case | B37: =I11 -> 55144.718 | C37: =(I11/D11)^(1/5)-1 -> 0.035144389 | D37: =I12 -> 6451.9321 | E37: =I13 -> 0.117
A38: Upside case | B38: =I21 -> 60509.71 | C38: =(I21/D21)^(1/5)-1 -> 0.05454511 | D38: =I22 -> 7987.2817 | E38: =I23 -> 0.132
A39: Downside case | B39: =I31 -> 47822.665 | C39: =(I31/D31)^(1/5)-1 -> 0.0060669966 | D39: =I32 -> 4877.9118 | E39: =I33 -> 0.102

Sheet Checks
A1: Checks
A2: All should be 0 (or OK).
A4: $ millions unless stated | B4: FY2024A | C4: FY2025A | D4: FY2026A | E4: FY2027E | F4: FY2028E | G4: FY2029E | H4: FY2030E | I4: FY2031E
A5: Balance sheet balances | B5: ='Balance Sheet'!B37 -> 0 | C5: ='Balance Sheet'!C37 -> 0 | D5: ='Balance Sheet'!D37 -> 0 | E5: ='Balance Sheet'!E37 -> 0 | F5: ='Balance Sheet'!F37 -> 0 | G5: ='Balance Sheet'!G37 -> 0 | H5: ='Balance Sheet'!H37 -> 0 | I5: ='Balance Sheet'!I37 -> 0
A6: Cash flow closing cash = balance sheet cash | B6: =ROUND('Cash Flow'!B32-'Balance Sheet'!B6,0) -> 0 | C6: =ROUND('Cash Flow'!C32-'Balance Sheet'!C6,0) -> 0 | D6: =ROUND('Cash Flow'!D32-'Balance Sheet'!D6,0) -> 0 | E6: =ROUND('Cash Flow'!E32-'Balance Sheet'!E6,0) -> 0 | F6: =ROUND('Cash Flow'!F32-'Balance Sheet'!F6,0) -> 0 | G6: =ROUND('Cash Flow'!G32-'Balance Sheet'!G6,0) -> 0 | H6: =ROUND('Cash Flow'!H32-'Balance Sheet'!H6,0) -> 0 | I6: =ROUND('Cash Flow'!I32-'Balance Sheet'!I6,0) -> 0
A7: Revenue build = income statement revenue | B7: =0 -> 0 | C7: =ROUND('Revenue Build'!C12-'Income Statement'!C5,0) -> 0 | D7: =ROUND('Revenue Build'!D12-'Income Statement'!D5,0) -> 0 | E7: =ROUND('Revenue Build'!E12-'Income Statement'!E5,0) -> 0 | F7: =ROUND('Revenue Build'!F12-'Income Statement'!F5,0) -> 0 | G7: =ROUND('Revenue Build'!G12-'Income Statement'!G5,0) -> 0 | H7: =ROUND('Revenue Build'!H12-'Income Statement'!H5,0) -> 0 | I7: =ROUND('Revenue Build'!I12-'Income Statement'!I5,0) -> 0
A8: Reported net income agrees (history) | B8: =ROUND('Income Statement'!B15-5700,0) -> 0 | C8: =ROUND('Income Statement'!C15-3219,0) -> 0 | D8: =ROUND('Income Statement'!D15-3108,0) -> 0 | E8: 0 | F8: 0 | G8: 0 | H8: 0 | I8: 0
A9: Reported total assets agree (history) | B9: =ROUND('Balance Sheet'!B16-38110,0) -> 0 | C9: =ROUND('Balance Sheet'!C16-36579,0) -> 0 | D9: =ROUND('Balance Sheet'!D16-38410,0) -> 0 | E9: 0 | F9: 0 | G9: 0 | H9: 0 | I9: 0
A10: Base case scenario sheet = model (when scenario 1 selected) | B10: 0 | C10: 0 | D10: 0 | E10: =IF(Assumptions!$B$6=1,ROUND(Scenarios!E11-'Income Statement'!E5,0),0) -> 0 | F10: =IF(Assumptions!$B$6=1,ROUND(Scenarios!F11-'Income Statement'!F5,0),0) -> 0 | G10: =IF(Assumptions!$B$6=1,ROUND(Scenarios!G11-'Income Statement'!G5,0),0) -> 0 | H10: =IF(Assumptions!$B$6=1,ROUND(Scenarios!H11-'Income Statement'!H5,0),0) -> 0 | I10: =IF(Assumptions!$B$6=1,ROUND(Scenarios!I11-'Income Statement'!I5,0),0) -> 0
A11: Cash stays positive | B11: ="OK" -> OK | C11: ="OK" -> OK | D11: ="OK" -> OK | E11: =IF('Balance Sheet'!E6>0,"OK","LOW CASH") -> OK | F11: =IF('Balance Sheet'!F6>0,"OK","LOW CASH") -> OK | G11: =IF('Balance Sheet'!G6>0,"OK","LOW CASH") -> OK | H11: =IF('Balance Sheet'!H6>0,"OK","LOW CASH") -> OK | I11: =IF('Balance Sheet'!I6>0,"OK","LOW CASH") -> OK
A13: Overall status | B13: =IF(AND(SUMPRODUCT(ABS(B5:I10))=0,COUNTIF(B11:I11,"OK")=8),"OK","ERROR") -> OK
